2021-09-15 17:18:15,617 ERROR: Exception on /reset_password_request [POST] [in d:\anaconda3\envs\flask\lib\site-packages\flask\app.py:1455]
Traceback (most recent call last):
  File "d:\anaconda3\envs\flask\lib\site-packages\flask\app.py", line 2070, in wsgi_app
    response = self.full_dispatch_request()
  File "d:\anaconda3\envs\flask\lib\site-packages\flask\app.py", line 1515, in full_dispatch_request
    rv = self.handle_user_exception(e)
  File "d:\anaconda3\envs\flask\lib\site-packages\flask\app.py", line 1513, in full_dispatch_request
    rv = self.dispatch_request()
  File "d:\anaconda3\envs\flask\lib\site-packages\flask\app.py", line 1499, in dispatch_request
    return self.ensure_sync(self.view_functions[rule.endpoint])(**req.view_args)
  File "E:\Code\python\FlaskStudy\MicroBlog\app\routes.py", line 163, in reset_password_request
    send_password_reset_email(user)
  File "E:\Code\python\FlaskStudy\MicroBlog\app\email.py", line 21, in send_password_reset_email
    user=user, token=token))
  File "E:\Code\python\FlaskStudy\MicroBlog\app\email.py", line 10, in send_email
    mail.send(msg)
  File "d:\anaconda3\envs\flask\lib\site-packages\flask_mail.py", line 491, in send
    with self.connect() as connection:
  File "d:\anaconda3\envs\flask\lib\site-packages\flask_mail.py", line 144, in __enter__
    self.host = self.configure_host()
  File "d:\anaconda3\envs\flask\lib\site-packages\flask_mail.py", line 165, in configure_host
    host.login(self.mail.username, self.mail.password)
  File "d:\anaconda3\envs\flask\lib\smtplib.py", line 730, in login
    raise last_exception
  File "d:\anaconda3\envs\flask\lib\smtplib.py", line 721, in login
    initial_response_ok=initial_response_ok)
  File "d:\anaconda3\envs\flask\lib\smtplib.py", line 642, in auth
    raise SMTPAuthenticationError(code, resp)
smtplib.SMTPAuthenticationError: (535, b'5.7.8 Username and Password not accepted. Learn more at\n5.7.8  https://support.google.com/mail/?p=BadCredentials t14sm13809410pga.62 - gsmtp')
