2021-09-15 17:02:37,944 ERROR: Exception on /reset_password_request [POST] [in d:\anaconda3\envs\flask\lib\site-packages\flask\app.py:1455]
Traceback (most recent call last):
  File "d:\anaconda3\envs\flask\lib\site-packages\flask\app.py", line 2070, in wsgi_app
    response = self.full_dispatch_request()
  File "d:\anaconda3\envs\flask\lib\site-packages\flask\app.py", line 1515, in full_dispatch_request
    rv = self.handle_user_exception(e)
  File "d:\anaconda3\envs\flask\lib\site-packages\flask\app.py", line 1513, in full_dispatch_request
    rv = self.dispatch_request()
  File "d:\anaconda3\envs\flask\lib\site-packages\flask\app.py", line 1499, in dispatch_request
    return self.ensure_sync(self.view_functions[rule.endpoint])(**req.view_args)
  File "E:\Code\python\FlaskStudy\MicroBlog\app\routes.py", line 163, in reset_password_request
    send_password_reset_email(user)
  File "E:\Code\python\FlaskStudy\MicroBlog\app\email.py", line 21, in send_password_reset_email
    user=user, token=token))
  File "E:\Code\python\FlaskStudy\MicroBlog\app\email.py", line 10, in send_email
    mail.send(msg)
  File "d:\anaconda3\envs\flask\lib\site-packages\flask_mail.py", line 491, in send
    with self.connect() as connection:
  File "d:\anaconda3\envs\flask\lib\site-packages\flask_mail.py", line 144, in __enter__
    self.host = self.configure_host()
  File "d:\anaconda3\envs\flask\lib\site-packages\flask_mail.py", line 158, in configure_host
    host = smtplib.SMTP(self.mail.server, self.mail.port)
  File "d:\anaconda3\envs\flask\lib\smtplib.py", line 251, in __init__
    (code, msg) = self.connect(host, port)
  File "d:\anaconda3\envs\flask\lib\smtplib.py", line 336, in connect
    self.sock = self._get_socket(host, port, self.timeout)
  File "d:\anaconda3\envs\flask\lib\smtplib.py", line 307, in _get_socket
    self.source_address)
  File "d:\anaconda3\envs\flask\lib\socket.py", line 728, in create_connection
    raise err
  File "d:\anaconda3\envs\flask\lib\socket.py", line 716, in create_connection
    sock.connect(sa)
ConnectionRefusedError: [WinError 10061] 由于目标计算机积极拒绝，无法连接。
2021-09-15 17:06:22,097 ERROR: Exception on /reset_password_request [POST] [in d:\anaconda3\envs\flask\lib\site-packages\flask\app.py:1455]
Traceback (most recent call last):
  File "d:\anaconda3\envs\flask\lib\site-packages\flask\app.py", line 2070, in wsgi_app
    response = self.full_dispatch_request()
  File "d:\anaconda3\envs\flask\lib\site-packages\flask\app.py", line 1515, in full_dispatch_request
    rv = self.handle_user_exception(e)
  File "d:\anaconda3\envs\flask\lib\site-packages\flask\app.py", line 1513, in full_dispatch_request
    rv = self.dispatch_request()
  File "d:\anaconda3\envs\flask\lib\site-packages\flask\app.py", line 1499, in dispatch_request
    return self.ensure_sync(self.view_functions[rule.endpoint])(**req.view_args)
  File "E:\Code\python\FlaskStudy\MicroBlog\app\routes.py", line 163, in reset_password_request
    send_password_reset_email(user)
  File "E:\Code\python\FlaskStudy\MicroBlog\app\email.py", line 21, in send_password_reset_email
    user=user, token=token))
  File "E:\Code\python\FlaskStudy\MicroBlog\app\email.py", line 10, in send_email
    mail.send(msg)
  File "d:\anaconda3\envs\flask\lib\site-packages\flask_mail.py", line 491, in send
    with self.connect() as connection:
  File "d:\anaconda3\envs\flask\lib\site-packages\flask_mail.py", line 144, in __enter__
    self.host = self.configure_host()
  File "d:\anaconda3\envs\flask\lib\site-packages\flask_mail.py", line 158, in configure_host
    host = smtplib.SMTP(self.mail.server, self.mail.port)
  File "d:\anaconda3\envs\flask\lib\smtplib.py", line 251, in __init__
    (code, msg) = self.connect(host, port)
  File "d:\anaconda3\envs\flask\lib\smtplib.py", line 336, in connect
    self.sock = self._get_socket(host, port, self.timeout)
  File "d:\anaconda3\envs\flask\lib\smtplib.py", line 307, in _get_socket
    self.source_address)
  File "d:\anaconda3\envs\flask\lib\socket.py", line 728, in create_connection
    raise err
  File "d:\anaconda3\envs\flask\lib\socket.py", line 716, in create_connection
    sock.connect(sa)
ConnectionRefusedError: [WinError 10061] 由于目标计算机积极拒绝，无法连接。
2021-09-15 17:06:39,126 ERROR: Exception on /reset_password_request [POST] [in d:\anaconda3\envs\flask\lib\site-packages\flask\app.py:1455]
Traceback (most recent call last):
  File "d:\anaconda3\envs\flask\lib\site-packages\flask\app.py", line 2070, in wsgi_app
    response = self.full_dispatch_request()
  File "d:\anaconda3\envs\flask\lib\site-packages\flask\app.py", line 1515, in full_dispatch_request
    rv = self.handle_user_exception(e)
  File "d:\anaconda3\envs\flask\lib\site-packages\flask\app.py", line 1513, in full_dispatch_request
    rv = self.dispatch_request()
  File "d:\anaconda3\envs\flask\lib\site-packages\flask\app.py", line 1499, in dispatch_request
    return self.ensure_sync(self.view_functions[rule.endpoint])(**req.view_args)
  File "E:\Code\python\FlaskStudy\MicroBlog\app\routes.py", line 163, in reset_password_request
    send_password_reset_email(user)
  File "E:\Code\python\FlaskStudy\MicroBlog\app\email.py", line 21, in send_password_reset_email
    user=user, token=token))
  File "E:\Code\python\FlaskStudy\MicroBlog\app\email.py", line 10, in send_email
    mail.send(msg)
  File "d:\anaconda3\envs\flask\lib\site-packages\flask_mail.py", line 491, in send
    with self.connect() as connection:
  File "d:\anaconda3\envs\flask\lib\site-packages\flask_mail.py", line 144, in __enter__
    self.host = self.configure_host()
  File "d:\anaconda3\envs\flask\lib\site-packages\flask_mail.py", line 158, in configure_host
    host = smtplib.SMTP(self.mail.server, self.mail.port)
  File "d:\anaconda3\envs\flask\lib\smtplib.py", line 251, in __init__
    (code, msg) = self.connect(host, port)
  File "d:\anaconda3\envs\flask\lib\smtplib.py", line 336, in connect
    self.sock = self._get_socket(host, port, self.timeout)
  File "d:\anaconda3\envs\flask\lib\smtplib.py", line 307, in _get_socket
    self.source_address)
  File "d:\anaconda3\envs\flask\lib\socket.py", line 728, in create_connection
    raise err
  File "d:\anaconda3\envs\flask\lib\socket.py", line 716, in create_connection
    sock.connect(sa)
ConnectionRefusedError: [WinError 10061] 由于目标计算机积极拒绝，无法连接。
2021-09-15 17:08:28,199 ERROR: Exception on /reset_password_request [POST] [in d:\anaconda3\envs\flask\lib\site-packages\flask\app.py:1455]
Traceback (most recent call last):
  File "d:\anaconda3\envs\flask\lib\site-packages\flask\app.py", line 2070, in wsgi_app
    response = self.full_dispatch_request()
  File "d:\anaconda3\envs\flask\lib\site-packages\flask\app.py", line 1515, in full_dispatch_request
    rv = self.handle_user_exception(e)
  File "d:\anaconda3\envs\flask\lib\site-packages\flask\app.py", line 1513, in full_dispatch_request
    rv = self.dispatch_request()
  File "d:\anaconda3\envs\flask\lib\site-packages\flask\app.py", line 1499, in dispatch_request
    return self.ensure_sync(self.view_functions[rule.endpoint])(**req.view_args)
  File "E:\Code\python\FlaskStudy\MicroBlog\app\routes.py", line 164, in reset_password_request
    send_password_reset_email(user)
  File "E:\Code\python\FlaskStudy\MicroBlog\app\email.py", line 21, in send_password_reset_email
    user=user, token=token))
  File "E:\Code\python\FlaskStudy\MicroBlog\app\email.py", line 10, in send_email
    mail.send(msg)
  File "d:\anaconda3\envs\flask\lib\site-packages\flask_mail.py", line 491, in send
    with self.connect() as connection:
  File "d:\anaconda3\envs\flask\lib\site-packages\flask_mail.py", line 144, in __enter__
    self.host = self.configure_host()
  File "d:\anaconda3\envs\flask\lib\site-packages\flask_mail.py", line 158, in configure_host
    host = smtplib.SMTP(self.mail.server, self.mail.port)
  File "d:\anaconda3\envs\flask\lib\smtplib.py", line 251, in __init__
    (code, msg) = self.connect(host, port)
  File "d:\anaconda3\envs\flask\lib\smtplib.py", line 336, in connect
    self.sock = self._get_socket(host, port, self.timeout)
  File "d:\anaconda3\envs\flask\lib\smtplib.py", line 307, in _get_socket
    self.source_address)
  File "d:\anaconda3\envs\flask\lib\socket.py", line 728, in create_connection
    raise err
  File "d:\anaconda3\envs\flask\lib\socket.py", line 716, in create_connection
    sock.connect(sa)
ConnectionRefusedError: [WinError 10061] 由于目标计算机积极拒绝，无法连接。
