2021-09-15 16:56:01,884 ERROR: Exception on /login/ [GET] [in d:\anaconda3\envs\flask\lib\site-packages\flask\app.py:1455]
Traceback (most recent call last):
  File "d:\anaconda3\envs\flask\lib\site-packages\flask\app.py", line 2070, in wsgi_app
    response = self.full_dispatch_request()
  File "d:\anaconda3\envs\flask\lib\site-packages\flask\app.py", line 1515, in full_dispatch_request
    rv = self.handle_user_exception(e)
  File "d:\anaconda3\envs\flask\lib\site-packages\flask\app.py", line 1513, in full_dispatch_request
    rv = self.dispatch_request()
  File "d:\anaconda3\envs\flask\lib\site-packages\flask\app.py", line 1499, in dispatch_request
    return self.ensure_sync(self.view_functions[rule.endpoint])(**req.view_args)
  File "E:\Code\python\FlaskStudy\MicroBlog\app\routes.py", line 72, in login
    return redirect(next_page)
  File "d:\anaconda3\envs\flask\lib\site-packages\flask\templating.py", line 150, in render_template
    ctx.app,
  File "d:\anaconda3\envs\flask\lib\site-packages\flask\templating.py", line 128, in _render
    rv = template.render(context)
  File "d:\anaconda3\envs\flask\lib\site-packages\jinja2\environment.py", line 1304, in render
    self.environment.handle_exception()
  File "d:\anaconda3\envs\flask\lib\site-packages\jinja2\environment.py", line 925, in handle_exception
    raise rewrite_traceback_stack(source=source)
  File "E:\Code\python\FlaskStudy\MicroBlog\app\templates\login.html", line 1, in top-level template code
    {% extends "base.html" %}
  File "E:\Code\python\FlaskStudy\MicroBlog\app\templates\base.html", line 34, in top-level template code
    {% block content %}{% endblock %}
  File "E:\Code\python\FlaskStudy\MicroBlog\app\templates\login.html", line 28, in block 'content'
    <a href="{{ url_for('reset_password_request') }}">Click to Reset It</a>
  File "d:\anaconda3\envs\flask\lib\site-packages\flask\helpers.py", line 338, in url_for
    return appctx.app.handle_url_build_error(error, endpoint, values)
  File "d:\anaconda3\envs\flask\lib\site-packages\flask\helpers.py", line 326, in url_for
    endpoint, values, method=method, force_external=external
  File "d:\anaconda3\envs\flask\lib\site-packages\werkzeug\routing.py", line 2305, in build
    raise BuildError(endpoint, values, method, self)
werkzeug.routing.BuildError: Could not build url for endpoint 'reset_password_request'. Did you mean 'edit_profile' instead?
2021-09-15 16:56:50,312 ERROR: Exception on /login/ [GET] [in d:\anaconda3\envs\flask\lib\site-packages\flask\app.py:1455]
Traceback (most recent call last):
  File "d:\anaconda3\envs\flask\lib\site-packages\flask\app.py", line 2070, in wsgi_app
    response = self.full_dispatch_request()
  File "d:\anaconda3\envs\flask\lib\site-packages\flask\app.py", line 1515, in full_dispatch_request
    rv = self.handle_user_exception(e)
  File "d:\anaconda3\envs\flask\lib\site-packages\flask\app.py", line 1513, in full_dispatch_request
    rv = self.dispatch_request()
  File "d:\anaconda3\envs\flask\lib\site-packages\flask\app.py", line 1499, in dispatch_request
    return self.ensure_sync(self.view_functions[rule.endpoint])(**req.view_args)
  File "E:\Code\python\FlaskStudy\MicroBlog\app\routes.py", line 72, in login
    return redirect(next_page)
  File "d:\anaconda3\envs\flask\lib\site-packages\flask\templating.py", line 150, in render_template
    ctx.app,
  File "d:\anaconda3\envs\flask\lib\site-packages\flask\templating.py", line 128, in _render
    rv = template.render(context)
  File "d:\anaconda3\envs\flask\lib\site-packages\jinja2\environment.py", line 1304, in render
    self.environment.handle_exception()
  File "d:\anaconda3\envs\flask\lib\site-packages\jinja2\environment.py", line 925, in handle_exception
    raise rewrite_traceback_stack(source=source)
  File "E:\Code\python\FlaskStudy\MicroBlog\app\templates\login.html", line 1, in top-level template code
    {% extends "base.html" %}
  File "E:\Code\python\FlaskStudy\MicroBlog\app\templates\base.html", line 34, in top-level template code
    {% block content %}{% endblock %}
  File "E:\Code\python\FlaskStudy\MicroBlog\app\templates\login.html", line 28, in block 'content'
    <a href="{{ url_for('reset_password_request') }}">Click to Reset It</a>
  File "d:\anaconda3\envs\flask\lib\site-packages\flask\helpers.py", line 338, in url_for
    return appctx.app.handle_url_build_error(error, endpoint, values)
  File "d:\anaconda3\envs\flask\lib\site-packages\flask\helpers.py", line 326, in url_for
    endpoint, values, method=method, force_external=external
  File "d:\anaconda3\envs\flask\lib\site-packages\werkzeug\routing.py", line 2305, in build
    raise BuildError(endpoint, values, method, self)
werkzeug.routing.BuildError: Could not build url for endpoint 'reset_password_request'. Did you mean 'edit_profile' instead?
2021-09-15 16:56:56,334 ERROR: Exception on /login/ [GET] [in d:\anaconda3\envs\flask\lib\site-packages\flask\app.py:1455]
Traceback (most recent call last):
  File "d:\anaconda3\envs\flask\lib\site-packages\flask\app.py", line 2070, in wsgi_app
    response = self.full_dispatch_request()
  File "d:\anaconda3\envs\flask\lib\site-packages\flask\app.py", line 1515, in full_dispatch_request
    rv = self.handle_user_exception(e)
  File "d:\anaconda3\envs\flask\lib\site-packages\flask\app.py", line 1513, in full_dispatch_request
    rv = self.dispatch_request()
  File "d:\anaconda3\envs\flask\lib\site-packages\flask\app.py", line 1499, in dispatch_request
    return self.ensure_sync(self.view_functions[rule.endpoint])(**req.view_args)
  File "E:\Code\python\FlaskStudy\MicroBlog\app\routes.py", line 72, in login
    return redirect(next_page)
  File "d:\anaconda3\envs\flask\lib\site-packages\flask\templating.py", line 150, in render_template
    ctx.app,
  File "d:\anaconda3\envs\flask\lib\site-packages\flask\templating.py", line 128, in _render
    rv = template.render(context)
  File "d:\anaconda3\envs\flask\lib\site-packages\jinja2\environment.py", line 1304, in render
    self.environment.handle_exception()
  File "d:\anaconda3\envs\flask\lib\site-packages\jinja2\environment.py", line 925, in handle_exception
    raise rewrite_traceback_stack(source=source)
  File "E:\Code\python\FlaskStudy\MicroBlog\app\templates\login.html", line 1, in top-level template code
    {% extends "base.html" %}
  File "E:\Code\python\FlaskStudy\MicroBlog\app\templates\base.html", line 34, in top-level template code
    {% block content %}{% endblock %}
  File "E:\Code\python\FlaskStudy\MicroBlog\app\templates\login.html", line 28, in block 'content'
    <a href="{{ url_for('reset_password_request') }}">Click to Reset It</a>
  File "d:\anaconda3\envs\flask\lib\site-packages\flask\helpers.py", line 338, in url_for
    return appctx.app.handle_url_build_error(error, endpoint, values)
  File "d:\anaconda3\envs\flask\lib\site-packages\flask\helpers.py", line 326, in url_for
    endpoint, values, method=method, force_external=external
  File "d:\anaconda3\envs\flask\lib\site-packages\werkzeug\routing.py", line 2305, in build
    raise BuildError(endpoint, values, method, self)
werkzeug.routing.BuildError: Could not build url for endpoint 'reset_password_request'. Did you mean 'edit_profile' instead?
2021-09-15 16:58:53,065 ERROR: Exception on /reset_password_request [POST] [in d:\anaconda3\envs\flask\lib\site-packages\flask\app.py:1455]
Traceback (most recent call last):
  File "d:\anaconda3\envs\flask\lib\site-packages\flask\app.py", line 2070, in wsgi_app
    response = self.full_dispatch_request()
  File "d:\anaconda3\envs\flask\lib\site-packages\flask\app.py", line 1515, in full_dispatch_request
    rv = self.handle_user_exception(e)
  File "d:\anaconda3\envs\flask\lib\site-packages\flask\app.py", line 1513, in full_dispatch_request
    rv = self.dispatch_request()
  File "d:\anaconda3\envs\flask\lib\site-packages\flask\app.py", line 1499, in dispatch_request
    return self.ensure_sync(self.view_functions[rule.endpoint])(**req.view_args)
  File "E:\Code\python\FlaskStudy\MicroBlog\app\routes.py", line 163, in reset_password_request
    send_password_reset_email(user)
  File "E:\Code\python\FlaskStudy\MicroBlog\app\email.py", line 14, in send_password_reset_email
    token = user.get_reset_password_token()
  File "E:\Code\python\FlaskStudy\MicroBlog\app\models.py", line 70, in get_reset_password_token
    {'reset_password': self.id, 'exp': time + expires_in},
TypeError: unsupported operand type(s) for +: 'builtin_function_or_method' and 'int'
2021-09-15 17:00:34,635 ERROR: Exception on /reset_password_request [POST] [in d:\anaconda3\envs\flask\lib\site-packages\flask\app.py:1455]
Traceback (most recent call last):
  File "d:\anaconda3\envs\flask\lib\site-packages\flask\app.py", line 2070, in wsgi_app
    response = self.full_dispatch_request()
  File "d:\anaconda3\envs\flask\lib\site-packages\flask\app.py", line 1515, in full_dispatch_request
    rv = self.handle_user_exception(e)
  File "d:\anaconda3\envs\flask\lib\site-packages\flask\app.py", line 1513, in full_dispatch_request
    rv = self.dispatch_request()
  File "d:\anaconda3\envs\flask\lib\site-packages\flask\app.py", line 1499, in dispatch_request
    return self.ensure_sync(self.view_functions[rule.endpoint])(**req.view_args)
  File "E:\Code\python\FlaskStudy\MicroBlog\app\routes.py", line 163, in reset_password_request
    send_password_reset_email(user)
  File "E:\Code\python\FlaskStudy\MicroBlog\app\email.py", line 14, in send_password_reset_email
    token = user.get_reset_password_token()
  File "E:\Code\python\FlaskStudy\MicroBlog\app\models.py", line 71, in get_reset_password_token
    app.config['SECRET_KEY'], algorithm='HS256'
AttributeError: 'str' object has no attribute 'decode'
